Traceback (most recent call last):
  File "/home/runner/micromamba-root/envs/buildenv/lib/python3.9/site-packages/jupyter_cache/executors/utils.py", line 51, in single_nb_execution
    executenb(
  File "/home/runner/micromamba-root/envs/buildenv/lib/python3.9/site-packages/nbclient/client.py", line 1204, in execute
    return NotebookClient(nb=nb, resources=resources, km=km, **kwargs).execute()
  File "/home/runner/micromamba-root/envs/buildenv/lib/python3.9/site-packages/nbclient/util.py", line 84, in wrapped
    return just_run(coro(*args, **kwargs))
  File "/home/runner/micromamba-root/envs/buildenv/lib/python3.9/site-packages/nbclient/util.py", line 62, in just_run
    return loop.run_until_complete(coro)
  File "/home/runner/micromamba-root/envs/buildenv/lib/python3.9/asyncio/base_events.py", line 647, in run_until_complete
    return future.result()
  File "/home/runner/micromamba-root/envs/buildenv/lib/python3.9/site-packages/nbclient/client.py", line 663, in async_execute
    await self.async_execute_cell(
  File "/home/runner/micromamba-root/envs/buildenv/lib/python3.9/site-packages/nbclient/client.py", line 965, in async_execute_cell
    await self._check_raise_for_error(cell, cell_index, exec_reply)
  File "/home/runner/micromamba-root/envs/buildenv/lib/python3.9/site-packages/nbclient/client.py", line 862, in _check_raise_for_error
    raise CellExecutionError.from_cell_and_msg(cell, exec_reply_content)
nbclient.exceptions.CellExecutionError: An error occurred while executing the following cell:
------------------
fig, ax = plt.subplots(1, 3)
labels = ["initial", "middle", "final"]
for i in range(3):
    ax[i].axis("off")
    ax[i].set_title(labels[i])
ase.visualize.plot.plot_atoms(traj[0], ax[0], radii=0.8, rotation=("-75x, 45y, 10z"))
ase.visualize.plot.plot_atoms(traj[50], ax[1], radii=0.8, rotation=("-75x, 45y, 10z"))
ase.visualize.plot.plot_atoms(traj[-1], ax[2], radii=0.8, rotation=("-75x, 45y, 10z"))
------------------

[0;31m---------------------------------------------------------------------------[0m
[0;31mNameError[0m                                 Traceback (most recent call last)
Cell [0;32mIn [3], line 1[0m
[0;32m----> 1[0m fig, ax [38;5;241m=[39m [43mplt[49m[38;5;241m.[39msubplots([38;5;241m1[39m, [38;5;241m3[39m)
[1;32m      2[0m labels [38;5;241m=[39m [[38;5;124m"[39m[38;5;124minitial[39m[38;5;124m"[39m, [38;5;124m"[39m[38;5;124mmiddle[39m[38;5;124m"[39m, [38;5;124m"[39m[38;5;124mfinal[39m[38;5;124m"[39m]
[1;32m      3[0m [38;5;28;01mfor[39;00m i [38;5;129;01min[39;00m [38;5;28mrange[39m([38;5;241m3[39m):

[0;31mNameError[0m: name 'plt' is not defined
NameError: name 'plt' is not defined

